Workbook

Sheet readme
A1: Implied Rates of Depreciation for Private Nonresidential Fixed Assets
A3: Worksheets in this file contain implied rates of depreciation calculated from unpublished fixed-cost investment and net capital
A4: stock of nonresidential fixed assets. The unpublished data that underlie these estimates are of significantly less quality than that
A5: of the higher level aggregates in which they are included. Compared to these aggregates, the detailed estimates are more likely
A6: to be either based on judgmental trends, on trends in the higher level aggregate, or on less reliable source data. Estimates are
A7: presented for detailed industries by selected major asset-types. The industries are identified by the NAICS-based BEA codes
A8: listed below.
A10: INDUSTRY TITLE | B10: BEA CODE | D10: 2017 NAICS Codes
A12: Agriculture, forestry, fishing, and hunting | B12: -------- | D12: 11
A13: Farms | B13: 110C | D13: 111112
A14: Forestry, fishing, and related activities | B14: 113F | D14: 113114115
A16: Mining | B16: -------- | D16: 21
A17: Oil and gas extraction | B17: 2110 | D17: 211
A18: Mining, except oil and gas | B18: 2120 | D18: 212
A19: Support activities for mining | B19: 2130 | D19: 213
A21: Utilities | B21: -------- | D21: 22
A22: Electric power | B22: 2211 | D22: 221
A23: Natural gas distribution | B23: 2212 | D23: 222
A24: Water, Sewage, and other systems | B24: 2213 | D24: 223
A26: Construction | B26: 2300 | D26: 23
A28: Manufacturing | B28: -------- | D28: 31-33
A29: Durable goods | B29: -------- | D29: --------
A30: Wood products | B30: 3210 | D30: 321
A31: Nonmetallic mineral products | B31: 3270 | D31: 327
A32: Primary metals | B32: 3310 | D32: 331
A33: Fabricated metal products | B33: 3320 | D33: 332
A34: Machinery | B34: 3330 | D34: 333
A35: Computer and electronic products | B35: 3340 | D35: 334
A36: Electrical equipment, appliances, and components | B36: 3350 | D36: 335
A37: Motor vehicles, bodies and trailers, and parts | B37: 336M | D37: 3361-3
A38: Other transportation equipment | B38: 336O | D38: 3364-9
A39: Furniture and related products | B39: 3370 | D39: 337
A40: Medical equipment and supplies | B40: 3380 | D40: 338
A41: Other manufacturing | B41: 3390 | D41: 339
A42: Nondurable goods | B42: -------- | D42: --------
A43: Food manufacturing | B43: 3110 | D43: 311
A44: Beverage, and tobacco product manufacturing | B44: 3120 | D44: 312
A45: Textile mills and textile product mills | B45: 313T | D45: 313, 314
A46: Apparel and leather and allied products | B46: 315A | D46: 315, 316
A47: Paper products | B47: 3220 | D47: 322
...

Sheet 110C
A1: 110C - Farms
A2: Implied Depreciation Rates for Private Nonresidential Fixed Assets
A3: Updated September 26, 2025
A5: Asset Codes | B5: NIPA Asset Types | C5: 1925 | D5: 1926 | E5: 1927 | F5: 1928 | G5: 1929 | H5: 1930 | I5: 1931 | J5: 1932 | K5: 1933 | L5: 1934 | M5: 1935 | N5: 1936 | O5: 1937 | P5: 1938 | Q5: 1939 | R5: 1940 | S5: 1941 | T5: 1942 | U5: 1943 | V5: 1944 | W5: 1945 | X5: 1946 | Y5: 1947 | Z5: 1948 | AA5: 1949 | AB5: 1950 | AC5: 1951 | AD5: 1952 | AE5: 1953 | AF5: 1954 | AG5: 1955 | AH5: 1956 | AI5: 1957 | AJ5: 1958 | AK5: 1959 | AL5: 1960 | AM5: 1961 | AN5: 1962 | AO5: 1963 | AP5: 1964 | AQ5: 1965 | AR5: 1966 | AS5: 1967 | AT5: 1968 | AU5: 1969 | AV5: 1970 | AW5: 1971 | AX5: 1972 | AY5: 1973 | AZ5: 1974 | BA5: 1975 | BB5: 1976 | BC5: 1977 | BD5: 1978 | BE5: 1979 | BF5: 1980 | BG5: 1981 | BH5: 1982 | BI5: 1983 | BJ5: 1984 | BK5: 1985 | BL5: 1986 | BM5: 1987 | BN5: 1988 | BO5: 1989 | BP5: 1990 | BQ5: 1991 | BR5: 1992 | BS5: 1993 | BT5: 1994 | BU5: 1995 | BV5: 1996 | BW5: 1997 | BX5: 1998 | BY5: 1999 | BZ5: 2000 | CA5: 2001 | CB5: 2002 | CC5: 2003 | CD5: 2004 | CE5: 2005 | CF5: 2006 | CG5: 2007 | CH5: 2008 | CI5: 2009 | CJ5: 2010 | CK5: 2011 | CL5: 2012 | CM5: 2013 | CN5: 2014 | CO5: 2015 | CP5: 2016 | CQ5: 2017 | CR5: 2018 | CS5: 2019 | CT5: 2020 | CU5: 2021 | CV5: 2022 | CW5: 2023 | CX5: 2024
A7: ES00 | B7: Equipment, structures, and intellectual property products | C7: =Datasets!B2 -> 0.0419 | D7: =Datasets!C2 -> 0.0434 | E7: =Datasets!D2 -> 0.0442 | F7: =Datasets!E2 -> 0.0451 | G7: =Datasets!F2 -> 0.0459 | H7: =Datasets!G2 -> 0.0466 | I7: =Datasets!H2 -> 0.0466 | J7: =Datasets!I2 -> 0.0456 | ... CX7: =Datasets!CW2 -> 0.0755
A8: EQ00 | B8: Equipment | C8: =Datasets!B3 -> 0.1349 | D8: =Datasets!C3 -> 0.1381 | E8: =Datasets!D3 -> 0.1384 | F8: =Datasets!E3 -> 0.1391 | G8: =Datasets!F3 -> 0.1395 | H8: =Datasets!G3 -> 0.1392 | I8: =Datasets!H3 -> 0.1389 | J8: =Datasets!I3 -> 0.1385 | ... CX8: =Datasets!CW3 -> 0.1331
A9: EP00 | B9: Information | C9: =Datasets!B4 -> 0 | D9: =Datasets!C4 -> 0 | E9: =Datasets!D4 -> 0 | F9: =Datasets!E4 -> 0 | G9: =Datasets!F4 -> 0 | H9: =Datasets!G4 -> 0 | I9: =Datasets!H4 -> 0 | J9: =Datasets!I4 -> 0 | ... CX9: =Datasets!CW4 -> 0.135
A10: EP11 | B10: Computers | C10: =Datasets!B5 -> 0 | D10: =Datasets!C5 -> 0 | E10: =Datasets!D5 -> 0 | F10: =Datasets!E5 -> 0 | G10: =Datasets!F5 -> 0 | H10: =Datasets!G5 -> 0 | I10: =Datasets!H5 -> 0 | J10: =Datasets!I5 -> 0 | ... CX10: =Datasets!CW5 -> 0.34
A11: EI00 | B11: Industrial | C11: =Datasets!B6 -> 0.1225 | D11: =Datasets!C6 -> 0.1225 | E11: =Datasets!D6 -> 0.1225 | F11: =Datasets!E6 -> 0.1225 | G11: =Datasets!F6 -> 0.1225 | H11: =Datasets!G6 -> 0.1225 | I11: =Datasets!H6 -> 0.1225 | J11: =Datasets!I6 -> 0.1225 | ... CX11: =Datasets!CW6 -> 0.0912
A12: ET00 | B12: Transportation | C12: =Datasets!B7 -> 0.2157 | D12: =Datasets!C7 -> 0.2254 | E12: =Datasets!D7 -> 0.2249 | F12: =Datasets!E7 -> 0.2277 | G12: =Datasets!F7 -> 0.2305 | H12: =Datasets!G7 -> 0.2326 | I12: =Datasets!H7 -> 0.2333 | J12: =Datasets!I7 -> 0.2307 | ... CX12: =Datasets!CW7 -> 0.1923
A13: EO00 | B13: Other equipment | C13: =Datasets!B8 -> 0.1245 | D13: =Datasets!C8 -> 0.1248 | E13: =Datasets!D8 -> 0.125 | F13: =Datasets!E8 -> 0.125 | G13: =Datasets!F8 -> 0.125 | H13: =Datasets!G8 -> 0.125 | I13: =Datasets!H8 -> 0.125 | J13: =Datasets!I8 -> 0.125 | ... CX13: =Datasets!CW8 -> 0.1254
A14: ST00 | B14: Structures | C14: =Datasets!B9 -> 0.0239 | D14: =Datasets!C9 -> 0.0239 | E14: =Datasets!D9 -> 0.0239 | F14: =Datasets!E9 -> 0.0239 | G14: =Datasets!F9 -> 0.0239 | H14: =Datasets!G9 -> 0.0239 | I14: =Datasets!H9 -> 0.0239 | J14: =Datasets!I9 -> 0.0239 | ... CX14: =Datasets!CW9 -> 0.0248
A15: SCHC | B15: Commercial and healthcare | C15: =Datasets!B10 -> 0 | D15: =Datasets!C10 -> 0 | E15: =Datasets!D10 -> 0 | F15: =Datasets!E10 -> 0 | G15: =Datasets!F10 -> 0 | H15: =Datasets!G10 -> 0 | I15: =Datasets!H10 -> 0 | J15: =Datasets!I10 -> 0 | ... CX15: =Datasets!CW10 -> 0
A16: IP00 | B16: Intellectual property products | C16: =Datasets!B11 -> 0 | D16: =Datasets!C11 -> 0 | E16: =Datasets!D11 -> 0 | F16: =Datasets!E11 -> 0 | G16: =Datasets!F11 -> 0 | H16: =Datasets!G11 -> 0 | I16: =Datasets!H11 -> 0 | J16: =Datasets!I11 -> 0 | ... CX16: =Datasets!CW11 -> 0.5191

Sheet 113F
A1: 113F - Forestry, Fishing, and Related Activities
A2: Implied Depreciation Rates for Private Nonresidential Fixed Assets
A3: Updated September 26, 2025
A5: Asset Codes | B5: NIPA Asset Types | C5: 1925 | D5: 1926 | E5: 1927 | F5: 1928 | G5: 1929 | H5: 1930 | I5: 1931 | J5: 1932 | K5: 1933 | L5: 1934 | M5: 1935 | N5: 1936 | O5: 1937 | P5: 1938 | Q5: 1939 | R5: 1940 | S5: 1941 | T5: 1942 | U5: 1943 | V5: 1944 | W5: 1945 | X5: 1946 | Y5: 1947 | Z5: 1948 | AA5: 1949 | AB5: 1950 | AC5: 1951 | AD5: 1952 | AE5: 1953 | AF5: 1954 | AG5: 1955 | AH5: 1956 | AI5: 1957 | AJ5: 1958 | AK5: 1959 | AL5: 1960 | AM5: 1961 | AN5: 1962 | AO5: 1963 | AP5: 1964 | AQ5: 1965 | AR5: 1966 | AS5: 1967 | AT5: 1968 | AU5: 1969 | AV5: 1970 | AW5: 1971 | AX5: 1972 | AY5: 1973 | AZ5: 1974 | BA5: 1975 | BB5: 1976 | BC5: 1977 | BD5: 1978 | BE5: 1979 | BF5: 1980 | BG5: 1981 | BH5: 1982 | BI5: 1983 | BJ5: 1984 | BK5: 1985 | BL5: 1986 | BM5: 1987 | BN5: 1988 | BO5: 1989 | BP5: 1990 | BQ5: 1991 | BR5: 1992 | BS5: 1993 | BT5: 1994 | BU5: 1995 | BV5: 1996 | BW5: 1997 | BX5: 1998 | BY5: 1999 | BZ5: 2000 | CA5: 2001 | CB5: 2002 | CC5: 2003 | CD5: 2004 | CE5: 2005 | CF5: 2006 | CG5: 2007 | CH5: 2008 | CI5: 2009 | CJ5: 2010 | CK5: 2011 | CL5: 2012 | CM5: 2013 | CN5: 2014 | CO5: 2015 | CP5: 2016 | CQ5: 2017 | CR5: 2018 | CS5: 2019 | CT5: 2020 | CU5: 2021 | CV5: 2022 | CW5: 2023 | CX5: 2024
A7: ES00 | B7: Equipment, structures, and intellectual property products | C7: =Datasets!B12 -> 0.0292 | D7: =Datasets!C12 -> 0.0328 | E7: =Datasets!D12 -> 0.0344 | F7: =Datasets!E12 -> 0.0359 | G7: =Datasets!F12 -> 0.0375 | H7: =Datasets!G12 -> 0.0385 | I7: =Datasets!H12 -> 0.0384 | J7: =Datasets!I12 -> 0.038 | ... CX7: =Datasets!CW12 -> 0.0947
A8: EQ00 | B8: Equipment | C8: =Datasets!B13 -> 0.1257 | D8: =Datasets!C13 -> 0.1436 | E8: =Datasets!D13 -> 0.1445 | F8: =Datasets!E13 -> 0.1461 | G8: =Datasets!F13 -> 0.1465 | H8: =Datasets!G13 -> 0.1418 | I8: =Datasets!H13 -> 0.1371 | J8: =Datasets!I13 -> 0.135 | ... CX8: =Datasets!CW13 -> 0.1222
A9: EP00 | B9: Information | C9: =Datasets!B14 -> 0 | D9: =Datasets!C14 -> 0 | E9: =Datasets!D14 -> 0 | F9: =Datasets!E14 -> 0 | G9: =Datasets!F14 -> 0 | H9: =Datasets!G14 -> 0 | I9: =Datasets!H14 -> 0 | J9: =Datasets!I14 -> 0 | ... CX9: =Datasets!CW14 -> 0.158
A10: EP11 | B10: Computers | C10: =Datasets!B15 -> 0 | D10: =Datasets!C15 -> 0 | E10: =Datasets!D15 -> 0 | F10: =Datasets!E15 -> 0 | G10: =Datasets!F15 -> 0 | H10: =Datasets!G15 -> 0 | I10: =Datasets!H15 -> 0 | J10: =Datasets!I15 -> 0 | ... CX10: =Datasets!CW15 -> 0.3397
A11: EI00 | B11: Industrial | C11: =Datasets!B16 -> 0.1027 | D11: =Datasets!C16 -> 0.1028 | E11: =Datasets!D16 -> 0.1029 | F11: =Datasets!E16 -> 0.1029 | G11: =Datasets!F16 -> 0.1028 | H11: =Datasets!G16 -> 0.1026 | I11: =Datasets!H16 -> 0.1025 | J11: =Datasets!I16 -> 0.1025 | ... CX11: =Datasets!CW16 -> 0.1049
A12: ET00 | B12: Transportation | C12: =Datasets!B17 -> 0.2387 | D12: =Datasets!C17 -> 0.2522 | E12: =Datasets!D17 -> 0.2527 | F12: =Datasets!E17 -> 0.2596 | G12: =Datasets!F17 -> 0.2507 | H12: =Datasets!G17 -> 0.2168 | I12: =Datasets!H17 -> 0.1945 | J12: =Datasets!I17 -> 0.188 | ... CX12: =Datasets!CW17 -> 0.1278
A13: EO00 | B13: Other equipment | C13: =Datasets!B18 -> 0 | D13: =Datasets!C18 -> 0 | E13: =Datasets!D18 -> 0 | F13: =Datasets!E18 -> 0 | G13: =Datasets!F18 -> 0 | H13: =Datasets!G18 -> 0 | I13: =Datasets!H18 -> 0 | J13: =Datasets!I18 -> 0 | ... CX13: =Datasets!CW18 -> 0.1237
A14: ST00 | B14: Structures | C14: =Datasets!B19 -> 0.023 | D14: =Datasets!C19 -> 0.0231 | E14: =Datasets!D19 -> 0.0231 | F14: =Datasets!E19 -> 0.0231 | G14: =Datasets!F19 -> 0.0231 | H14: =Datasets!G19 -> 0.0231 | I14: =Datasets!H19 -> 0.0231 | J14: =Datasets!I19 -> 0.0231 | ... CX14: =Datasets!CW19 -> 0.0251
A15: SCHC | B15: Commercial and healthcare | C15: =Datasets!B20 -> 0.0247 | D15: =Datasets!C20 -> 0.0247 | E15: =Datasets!D20 -> 0.0247 | F15: =Datasets!E20 -> 0.0247 | G15: =Datasets!F20 -> 0.0247 | H15: =Datasets!G20 -> 0.0247 | I15: =Datasets!H20 -> 0.0247 | J15: =Datasets!I20 -> 0.0247 | ... CX15: =Datasets!CW20 -> 0.0243
A16: IP00 | B16: Intellectual property products | C16: =Datasets!B21 -> 0 | D16: =Datasets!C21 -> 0 | E16: =Datasets!D21 -> 0 | F16: =Datasets!E21 -> 0 | G16: =Datasets!F21 -> 0 | H16: =Datasets!G21 -> 0 | I16: =Datasets!H21 -> 0 | J16: =Datasets!I21 -> 0 | ... CX16: =Datasets!CW21 -> 0.4258

Sheet 2110
A1: 2110 - Oil and Gas Extraction
A2: Implied Depreciation Rates for Private Nonresidential Fixed Assets
A3: Updated September 26, 2025
A5: Asset Codes | B5: NIPA Asset Types | C5: 1925 | D5: 1926 | E5: 1927 | F5: 1928 | G5: 1929 | H5: 1930 | I5: 1931 | J5: 1932 | K5: 1933 | L5: 1934 | M5: 1935 | N5: 1936 | O5: 1937 | P5: 1938 | Q5: 1939 | R5: 1940 | S5: 1941 | T5: 1942 | U5: 1943 | V5: 1944 | W5: 1945 | X5: 1946 | Y5: 1947 | Z5: 1948 | AA5: 1949 | AB5: 1950 | AC5: 1951 | AD5: 1952 | AE5: 1953 | AF5: 1954 | AG5: 1955 | AH5: 1956 | AI5: 1957 | AJ5: 1958 | AK5: 1959 | AL5: 1960 | AM5: 1961 | AN5: 1962 | AO5: 1963 | AP5: 1964 | AQ5: 1965 | AR5: 1966 | AS5: 1967 | AT5: 1968 | AU5: 1969 | AV5: 1970 | AW5: 1971 | AX5: 1972 | AY5: 1973 | AZ5: 1974 | BA5: 1975 | BB5: 1976 | BC5: 1977 | BD5: 1978 | BE5: 1979 | BF5: 1980 | BG5: 1981 | BH5: 1982 | BI5: 1983 | BJ5: 1984 | BK5: 1985 | BL5: 1986 | BM5: 1987 | BN5: 1988 | BO5: 1989 | BP5: 1990 | BQ5: 1991 | BR5: 1992 | BS5: 1993 | BT5: 1994 | BU5: 1995 | BV5: 1996 | BW5: 1997 | BX5: 1998 | BY5: 1999 | BZ5: 2000 | CA5: 2001 | CB5: 2002 | CC5: 2003 | CD5: 2004 | CE5: 2005 | CF5: 2006 | CG5: 2007 | CH5: 2008 | CI5: 2009 | CJ5: 2010 | CK5: 2011 | CL5: 2012 | CM5: 2013 | CN5: 2014 | CO5: 2015 | CP5: 2016 | CQ5: 2017 | CR5: 2018 | CS5: 2019 | CT5: 2020 | CU5: 2021 | CV5: 2022 | CW5: 2023 | CX5: 2024
A7: ES00 | B7: Equipment, structures, and intellectual property products | C7: =Datasets!B22 -> 0.0537 | D7: =Datasets!C22 -> 0.0539 | E7: =Datasets!D22 -> 0.0539 | F7: =Datasets!E22 -> 0.0539 | G7: =Datasets!F22 -> 0.054 | H7: =Datasets!G22 -> 0.0541 | I7: =Datasets!H22 -> 0.0542 | J7: =Datasets!I22 -> 0.0542 | ... CX7: =Datasets!CW22 -> 0.0738
A8: EQ00 | B8: Equipment | C8: =Datasets!B23 -> 0.1695 | D8: =Datasets!C23 -> 0.1807 | E8: =Datasets!D23 -> 0.1739 | F8: =Datasets!E23 -> 0.1728 | G8: =Datasets!F23 -> 0.1688 | H8: =Datasets!G23 -> 0.1648 | I8: =Datasets!H23 -> 0.1644 | J8: =Datasets!I23 -> 0.1623 | ... CX8: =Datasets!CW23 -> 0.1283
A9: EP00 | B9: Information | C9: =Datasets!B24 -> 0 | D9: =Datasets!C24 -> 0 | E9: =Datasets!D24 -> 0 | F9: =Datasets!E24 -> 0 | G9: =Datasets!F24 -> 0 | H9: =Datasets!G24 -> 0 | I9: =Datasets!H24 -> 0 | J9: =Datasets!I24 -> 0 | ... CX9: =Datasets!CW24 -> 0.1807
A10: EP11 | B10: Computers | C10: =Datasets!B25 -> 0 | D10: =Datasets!C25 -> 0 | E10: =Datasets!D25 -> 0 | F10: =Datasets!E25 -> 0 | G10: =Datasets!F25 -> 0 | H10: =Datasets!G25 -> 0 | I10: =Datasets!H25 -> 0 | J10: =Datasets!I25 -> 0 | ... CX10: =Datasets!CW25 -> 0.3431
A11: EI00 | B11: Industrial | C11: =Datasets!B26 -> 0.0948 | D11: =Datasets!C26 -> 0.0952 | E11: =Datasets!D26 -> 0.0944 | F11: =Datasets!E26 -> 0.0925 | G11: =Datasets!F26 -> 0.0913 | H11: =Datasets!G26 -> 0.0909 | I11: =Datasets!H26 -> 0.0901 | J11: =Datasets!I26 -> 0.0895 | ... CX11: =Datasets!CW26 -> 0.106
A12: ET00 | B12: Transportation | C12: =Datasets!B27 -> 0.2387 | D12: =Datasets!C27 -> 0.2522 | E12: =Datasets!D27 -> 0.2527 | F12: =Datasets!E27 -> 0.2596 | G12: =Datasets!F27 -> 0.2648 | H12: =Datasets!G27 -> 0.2671 | I12: =Datasets!H27 -> 0.2669 | J12: =Datasets!I27 -> 0.2601 | ... CX12: =Datasets!CW27 -> 0.0754
A13: EO00 | B13: Other equipment | C13: =Datasets!B28 -> 0 | D13: =Datasets!C28 -> 0 | E13: =Datasets!D28 -> 0 | F13: =Datasets!E28 -> 0 | G13: =Datasets!F28 -> 0 | H13: =Datasets!G28 -> 0.15 | I13: =Datasets!H28 -> 0.15 | J13: =Datasets!I28 -> 0.15 | ... CX13: =Datasets!CW28 -> 0.1502
A14: ST00 | B14: Structures | C14: =Datasets!B29 -> 0.0533 | D14: =Datasets!C29 -> 0.0533 | E14: =Datasets!D29 -> 0.0532 | F14: =Datasets!E29 -> 0.0533 | G14: =Datasets!F29 -> 0.0533 | H14: =Datasets!G29 -> 0.0534 | I14: =Datasets!H29 -> 0.0534 | J14: =Datasets!I29 -> 0.0534 | ... CX14: =Datasets!CW29 -> 0.0703
A15: SCHC | B15: Commercial and healthcare | C15: =Datasets!B30 -> 0.0247 | D15: =Datasets!C30 -> 0.0247 | E15: =Datasets!D30 -> 0.0247 | F15: =Datasets!E30 -> 0.0247 | G15: =Datasets!F30 -> 0.0247 | H15: =Datasets!G30 -> 0.0247 | I15: =Datasets!H30 -> 0.0247 | J15: =Datasets!I30 -> 0.0247 | ... CX15: =Datasets!CW30 -> 0.0258
A16: IP00 | B16: Intellectual property products | C16: =Datasets!B31 -> 0.16 | D16: =Datasets!C31 -> 0.16 | E16: =Datasets!D31 -> 0.16 | F16: =Datasets!E31 -> 0.16 | G16: =Datasets!F31 -> 0.16 | H16: =Datasets!G31 -> 0.16 | I16: =Datasets!H31 -> 0.16 | J16: =Datasets!I31 -> 0.16 | ... CX16: =Datasets!CW31 -> 0.1682

Sheet 2120
A1: 2120 - Mining, Except Oil and Gas
A2: Implied Depreciation Rates for Private Nonresidential Fixed Assets
A3: Updated September 26, 2025
A5: Asset Codes | B5: NIPA Asset Types | C5: 1925 | D5: 1926 | E5: 1927 | F5: 1928 | G5: 1929 | H5: 1930 | I5: 1931 | J5: 1932 | K5: 1933 | L5: 1934 | M5: 1935 | N5: 1936 | O5: 1937 | P5: 1938 | Q5: 1939 | R5: 1940 | S5: 1941 | T5: 1942 | U5: 1943 | V5: 1944 | W5: 1945 | X5: 1946 | Y5: 1947 | Z5: 1948 | AA5: 1949 | AB5: 1950 | AC5: 1951 | AD5: 1952 | AE5: 1953 | AF5: 1954 | AG5: 1955 | AH5: 1956 | AI5: 1957 | AJ5: 1958 | AK5: 1959 | AL5: 1960 | AM5: 1961 | AN5: 1962 | AO5: 1963 | AP5: 1964 | AQ5: 1965 | AR5: 1966 | AS5: 1967 | AT5: 1968 | AU5: 1969 | AV5: 1970 | AW5: 1971 | AX5: 1972 | AY5: 1973 | AZ5: 1974 | BA5: 1975 | BB5: 1976 | BC5: 1977 | BD5: 1978 | BE5: 1979 | BF5: 1980 | BG5: 1981 | BH5: 1982 | BI5: 1983 | BJ5: 1984 | BK5: 1985 | BL5: 1986 | BM5: 1987 | BN5: 1988 | BO5: 1989 | BP5: 1990 | BQ5: 1991 | BR5: 1992 | BS5: 1993 | BT5: 1994 | BU5: 1995 | BV5: 1996 | BW5: 1997 | BX5: 1998 | BY5: 1999 | BZ5: 2000 | CA5: 2001 | CB5: 2002 | CC5: 2003 | CD5: 2004 | CE5: 2005 | CF5: 2006 | CG5: 2007 | CH5: 2008 | CI5: 2009 | CJ5: 2010 | CK5: 2011 | CL5: 2012 | CM5: 2013 | CN5: 2014 | CO5: 2015 | CP5: 2016 | CQ5: 2017 | CR5: 2018 | CS5: 2019 | CT5: 2020 | CU5: 2021 | CV5: 2022 | CW5: 2023 | CX5: 2024
A7: ES00 | B7: Equipment, structures, and intellectual property products | C7: =Datasets!B32 -> 0.0359 | D7: =Datasets!C32 -> 0.037 | E7: =Datasets!D32 -> 0.0377 | F7: =Datasets!E32 -> 0.0381 | G7: =Datasets!F32 -> 0.0388 | H7: =Datasets!G32 -> 0.0404 | I7: =Datasets!H32 -> 0.0419 | J7: =Datasets!I32 -> 0.0424 | ... CX7: =Datasets!CW32 -> 0.0654
A8: EQ00 | B8: Equipment | C8: =Datasets!B33 -> 0.1216 | D8: =Datasets!C33 -> 0.1279 | E8: =Datasets!D33 -> 0.1259 | F8: =Datasets!E33 -> 0.1257 | G8: =Datasets!F33 -> 0.1247 | H8: =Datasets!G33 -> 0.1291 | I8: =Datasets!H33 -> 0.1343 | J8: =Datasets!I33 -> 0.136 | ... CX8: =Datasets!CW33 -> 0.1417
A9: EP00 | B9: Information | C9: =Datasets!B34 -> 0 | D9: =Datasets!C34 -> 0 | E9: =Datasets!D34 -> 0 | F9: =Datasets!E34 -> 0 | G9: =Datasets!F34 -> 0 | H9: =Datasets!G34 -> 0 | I9: =Datasets!H34 -> 0 | J9: =Datasets!I34 -> 0 | ... CX9: =Datasets!CW34 -> 0.1517
A10: EP11 | B10: Computers | C10: =Datasets!B35 -> 0 | D10: =Datasets!C35 -> 0 | E10: =Datasets!D35 -> 0 | F10: =Datasets!E35 -> 0 | G10: =Datasets!F35 -> 0 | H10: =Datasets!G35 -> 0 | I10: =Datasets!H35 -> 0 | J10: =Datasets!I35 -> 0 | ... CX10: =Datasets!CW35 -> 0.3383
A11: EI00 | B11: Industrial | C11: =Datasets!B36 -> 0.0996 | D11: =Datasets!C36 -> 0.0997 | E11: =Datasets!D36 -> 0.0997 | F11: =Datasets!E36 -> 0.099 | G11: =Datasets!F36 -> 0.0987 | H11: =Datasets!G36 -> 0.0984 | I11: =Datasets!H36 -> 0.0978 | J11: =Datasets!I36 -> 0.0973 | ... CX11: =Datasets!CW36 -> 0.0994
A12: ET00 | B12: Transportation | C12: =Datasets!B37 -> 0.2387 | D12: =Datasets!C37 -> 0.2522 | E12: =Datasets!D37 -> 0.2527 | F12: =Datasets!E37 -> 0.2596 | G12: =Datasets!F37 -> 0.2659 | H12: =Datasets!G37 -> 0.2693 | I12: =Datasets!H37 -> 0.269 | J12: =Datasets!I37 -> 0.2621 | ... CX12: =Datasets!CW37 -> 0.1496
A13: EO00 | B13: Other equipment | C13: =Datasets!B38 -> 0 | D13: =Datasets!C38 -> 0 | E13: =Datasets!D38 -> 0 | F13: =Datasets!E38 -> 0 | G13: =Datasets!F38 -> 0.1633 | H13: =Datasets!G38 -> 0.1514 | I13: =Datasets!H38 -> 0.1508 | J13: =Datasets!I38 -> 0.1508 | ... CX13: =Datasets!CW38 -> 0.1522
A14: ST00 | B14: Structures | C14: =Datasets!B39 -> 0.0334 | D14: =Datasets!C39 -> 0.0335 | E14: =Datasets!D39 -> 0.0336 | F14: =Datasets!E39 -> 0.0337 | G14: =Datasets!F39 -> 0.0338 | H14: =Datasets!G39 -> 0.0339 | I14: =Datasets!H39 -> 0.034 | J14: =Datasets!I39 -> 0.0341 | ... CX14: =Datasets!CW39 -> 0.0413
A15: SCHC | B15: Commercial and healthcare | C15: =Datasets!B40 -> 0.0247 | D15: =Datasets!C40 -> 0.0247 | E15: =Datasets!D40 -> 0.0247 | F15: =Datasets!E40 -> 0.0247 | G15: =Datasets!F40 -> 0.0247 | H15: =Datasets!G40 -> 0.0247 | I15: =Datasets!H40 -> 0.0247 | J15: =Datasets!I40 -> 0.0247 | ... CX15: =Datasets!CW40 -> 0.0272
A16: IP00 | B16: Intellectual property products | C16: =Datasets!B41 -> 0.16 | D16: =Datasets!C41 -> 0.16 | E16: =Datasets!D41 -> 0.16 | F16: =Datasets!E41 -> 0.16 | G16: =Datasets!F41 -> 0.16 | H16: =Datasets!G41 -> 0.16 | I16: =Datasets!H41 -> 0.16 | J16: =Datasets!I41 -> 0.16 | ... CX16: =Datasets!CW41 -> 0.1838

Sheet 2130
A1: 2130 - Support Activites for Mining
A2: Implied Depreciation Rates for Private Nonresidential Fixed Assets
A3: Updated September 26, 2025
A5: Asset Codes | B5: NIPA Asset Types | C5: 1925 | D5: 1926 | E5: 1927 | F5: 1928 | G5: 1929 | H5: 1930 | I5: 1931 | J5: 1932 | K5: 1933 | L5: 1934 | M5: 1935 | N5: 1936 | O5: 1937 | P5: 1938 | Q5: 1939 | R5: 1940 | S5: 1941 | T5: 1942 | U5: 1943 | V5: 1944 | W5: 1945 | X5: 1946 | Y5: 1947 | Z5: 1948 | AA5: 1949 | AB5: 1950 | AC5: 1951 | AD5: 1952 | AE5: 1953 | AF5: 1954 | AG5: 1955 | AH5: 1956 | AI5: 1957 | AJ5: 1958 | AK5: 1959 | AL5: 1960 | AM5: 1961 | AN5: 1962 | AO5: 1963 | AP5: 1964 | AQ5: 1965 | AR5: 1966 | AS5: 1967 | AT5: 1968 | AU5: 1969 | AV5: 1970 | AW5: 1971 | AX5: 1972 | AY5: 1973 | AZ5: 1974 | BA5: 1975 | BB5: 1976 | BC5: 1977 | BD5: 1978 | BE5: 1979 | BF5: 1980 | BG5: 1981 | BH5: 1982 | BI5: 1983 | BJ5: 1984 | BK5: 1985 | BL5: 1986 | BM5: 1987 | BN5: 1988 | BO5: 1989 | BP5: 1990 | BQ5: 1991 | BR5: 1992 | BS5: 1993 | BT5: 1994 | BU5: 1995 | BV5: 1996 | BW5: 1997 | BX5: 1998 | BY5: 1999 | BZ5: 2000 | CA5: 2001 | CB5: 2002 | CC5: 2003 | CD5: 2004 | CE5: 2005 | CF5: 2006 | CG5: 2007 | CH5: 2008 | CI5: 2009 | CJ5: 2010 | CK5: 2011 | CL5: 2012 | CM5: 2013 | CN5: 2014 | CO5: 2015 | CP5: 2016 | CQ5: 2017 | CR5: 2018 | CS5: 2019 | CT5: 2020 | CU5: 2021 | CV5: 2022 | CW5: 2023 | CX5: 2024
A7: ES00 | B7: Equipment, structures, and intellectual property products | C7: =Datasets!B42 -> 0.0614 | D7: =Datasets!C42 -> 0.063 | E7: =Datasets!D42 -> 0.0633 | F7: =Datasets!E42 -> 0.0635 | G7: =Datasets!F42 -> 0.0639 | H7: =Datasets!G42 -> 0.0647 | I7: =Datasets!H42 -> 0.0653 | J7: =Datasets!I42 -> 0.0652 | ... CX7: =Datasets!CW42 -> 0.088
A8: EQ00 | B8: Equipment | C8: =Datasets!B43 -> 0.1363 | D8: =Datasets!C43 -> 0.1404 | E8: =Datasets!D43 -> 0.1339 | F8: =Datasets!E43 -> 0.131 | G8: =Datasets!F43 -> 0.127 | H8: =Datasets!G43 -> 0.1268 | I8: =Datasets!H43 -> 0.1297 | J8: =Datasets!I43 -> 0.1299 | ... CX8: =Datasets!CW43 -> 0.1244
A9: EP00 | B9: Information | C9: =Datasets!B44 -> 0 | D9: =Datasets!C44 -> 0 | E9: =Datasets!D44 -> 0 | F9: =Datasets!E44 -> 0 | G9: =Datasets!F44 -> 0 | H9: =Datasets!G44 -> 0 | I9: =Datasets!H44 -> 0 | J9: =Datasets!I44 -> 0 | ... CX9: =Datasets!CW44 -> 0.1753
A10: EP11 | B10: Computers | C10: =Datasets!B45 -> 0 | D10: =Datasets!C45 -> 0 | E10: =Datasets!D45 -> 0 | F10: =Datasets!E45 -> 0 | G10: =Datasets!F45 -> 0 | H10: =Datasets!G45 -> 0 | I10: =Datasets!H45 -> 0 | J10: =Datasets!I45 -> 0 | ... CX10: =Datasets!CW45 -> 0.3387
A11: EI00 | B11: Industrial | C11: =Datasets!B46 -> 0.0939 | D11: =Datasets!C46 -> 0.0944 | E11: =Datasets!D46 -> 0.0939 | F11: =Datasets!E46 -> 0.0922 | G11: =Datasets!F46 -> 0.0911 | H11: =Datasets!G46 -> 0.0907 | I11: =Datasets!H46 -> 0.09 | J11: =Datasets!I46 -> 0.0893 | ... CX11: =Datasets!CW46 -> 0.0762
A12: ET00 | B12: Transportation | C12: =Datasets!B47 -> 0.2387 | D12: =Datasets!C47 -> 0.2522 | E12: =Datasets!D47 -> 0.2527 | F12: =Datasets!E47 -> 0.2596 | G12: =Datasets!F47 -> 0.2659 | H12: =Datasets!G47 -> 0.2693 | I12: =Datasets!H47 -> 0.269 | J12: =Datasets!I47 -> 0.2621 | ... CX12: =Datasets!CW47 -> 0.0944
A13: EO00 | B13: Other equipment | C13: =Datasets!B48 -> 0 | D13: =Datasets!C48 -> 0 | E13: =Datasets!D48 -> 0 | F13: =Datasets!E48 -> 0 | G13: =Datasets!F48 -> 0.1633 | H13: =Datasets!G48 -> 0.1507 | I13: =Datasets!H48 -> 0.1504 | J13: =Datasets!I48 -> 0.1504 | ... CX13: =Datasets!CW48 -> 0.1504
A14: ST00 | B14: Structures | C14: =Datasets!B49 -> 0.0556 | D14: =Datasets!C49 -> 0.0556 | E14: =Datasets!D49 -> 0.0556 | F14: =Datasets!E49 -> 0.0556 | G14: =Datasets!F49 -> 0.0556 | H14: =Datasets!G49 -> 0.0556 | I14: =Datasets!H49 -> 0.0556 | J14: =Datasets!I49 -> 0.0555 | ... CX14: =Datasets!CW49 -> 0.0522
A15: SCHC | B15: Commercial and healthcare | C15: =Datasets!B50 -> 0.0247 | D15: =Datasets!C50 -> 0.0247 | E15: =Datasets!D50 -> 0.0247 | F15: =Datasets!E50 -> 0.0247 | G15: =Datasets!F50 -> 0.0247 | H15: =Datasets!G50 -> 0.0247 | I15: =Datasets!H50 -> 0.0247 | J15: =Datasets!I50 -> 0.0247 | ... CX15: =Datasets!CW50 -> 0.0256
A16: IP00 | B16: Intellectual property products | C16: =Datasets!B51 -> 0.16 | D16: =Datasets!C51 -> 0.16 | E16: =Datasets!D51 -> 0.16 | F16: =Datasets!E51 -> 0.16 | G16: =Datasets!F51 -> 0.16 | H16: =Datasets!G51 -> 0.16 | I16: =Datasets!H51 -> 0.16 | J16: =Datasets!I51 -> 0.16 | ... CX16: =Datasets!CW51 -> 0.2394

Sheet 2211
A1: 2211 - Electric Power
A2: Implied Depreciation Rates for Private Nonresidential Fixed Assets
A3: Updated September 26, 2025
A5: Asset Codes | B5: NIPA Asset Types | C5: 1925 | D5: 1926 | E5: 1927 | F5: 1928 | G5: 1929 | H5: 1930 | I5: 1931 | J5: 1932 | K5: 1933 | L5: 1934 | M5: 1935 | N5: 1936 | O5: 1937 | P5: 1938 | Q5: 1939 | R5: 1940 | S5: 1941 | T5: 1942 | U5: 1943 | V5: 1944 | W5: 1945 | X5: 1946 | Y5: 1947 | Z5: 1948 | AA5: 1949 | AB5: 1950 | AC5: 1951 | AD5: 1952 | AE5: 1953 | AF5: 1954 | AG5: 1955 | AH5: 1956 | AI5: 1957 | AJ5: 1958 | AK5: 1959 | AL5: 1960 | AM5: 1961 | AN5: 1962 | AO5: 1963 | AP5: 1964 | AQ5: 1965 | AR5: 1966 | AS5: 1967 | AT5: 1968 | AU5: 1969 | AV5: 1970 | AW5: 1971 | AX5: 1972 | AY5: 1973 | AZ5: 1974 | BA5: 1975 | BB5: 1976 | BC5: 1977 | BD5: 1978 | BE5: 1979 | BF5: 1980 | BG5: 1981 | BH5: 1982 | BI5: 1983 | BJ5: 1984 | BK5: 1985 | BL5: 1986 | BM5: 1987 | BN5: 1988 | BO5: 1989 | BP5: 1990 | BQ5: 1991 | BR5: 1992 | BS5: 1993 | BT5: 1994 | BU5: 1995 | BV5: 1996 | BW5: 1997 | BX5: 1998 | BY5: 1999 | BZ5: 2000 | CA5: 2001 | CB5: 2002 | CC5: 2003 | CD5: 2004 | CE5: 2005 | CF5: 2006 | CG5: 2007 | CH5: 2008 | CI5: 2009 | CJ5: 2010 | CK5: 2011 | CL5: 2012 | CM5: 2013 | CN5: 2014 | CO5: 2015 | CP5: 2016 | CQ5: 2017 | CR5: 2018 | CS5: 2019 | CT5: 2020 | CU5: 2021 | CV5: 2022 | CW5: 2023 | CX5: 2024
A7: ES00 | B7: Equipment, structures, and intellectual property products | C7: =Datasets!B52 -> 0.0256 | D7: =Datasets!C52 -> 0.0259 | E7: =Datasets!D52 -> 0.0258 | F7: =Datasets!E52 -> 0.0258 | G7: =Datasets!F52 -> 0.0258 | H7: =Datasets!G52 -> 0.0257 | I7: =Datasets!H52 -> 0.0256 | J7: =Datasets!I52 -> 0.0256 | ... CX7: =Datasets!CW52 -> 0.0403
A8: EQ00 | B8: Equipment | C8: =Datasets!B53 -> 0.0772 | D8: =Datasets!C53 -> 0.0841 | E8: =Datasets!D53 -> 0.0847 | F8: =Datasets!E53 -> 0.0861 | G8: =Datasets!F53 -> 0.0876 | H8: =Datasets!G53 -> 0.0879 | I8: =Datasets!H53 -> 0.0867 | J8: =Datasets!I53 -> 0.0848 | ... CX8: =Datasets!CW53 -> 0.0645
A9: EP00 | B9: Information | C9: =Datasets!B54 -> 0 | D9: =Datasets!C54 -> 0 | E9: =Datasets!D54 -> 0.11 | F9: =Datasets!E54 -> 0.11 | G9: =Datasets!F54 -> 0.11 | H9: =Datasets!G54 -> 0.11 | I9: =Datasets!H54 -> 0.1195 | J9: =Datasets!I54 -> 0.1288 | ... CX9: =Datasets!CW54 -> 0.1563
A10: EP11 | B10: Computers | C10: =Datasets!B55 -> 0 | D10: =Datasets!C55 -> 0 | E10: =Datasets!D55 -> 0 | F10: =Datasets!E55 -> 0 | G10: =Datasets!F55 -> 0 | H10: =Datasets!G55 -> 0 | I10: =Datasets!H55 -> 0 | J10: =Datasets!I55 -> 0 | ... CX10: =Datasets!CW55 -> 0.3373
A11: EI00 | B11: Industrial | C11: =Datasets!B56 -> 0.0523 | D11: =Datasets!C56 -> 0.0527 | E11: =Datasets!D56 -> 0.0529 | F11: =Datasets!E56 -> 0.0529 | G11: =Datasets!F56 -> 0.0528 | H11: =Datasets!G56 -> 0.053 | I11: =Datasets!H56 -> 0.0533 | J11: =Datasets!I56 -> 0.0534 | ... CX11: =Datasets!CW56 -> 0.0563
A12: ET00 | B12: Transportation | C12: =Datasets!B57 -> 0.2387 | D12: =Datasets!C57 -> 0.2522 | E12: =Datasets!D57 -> 0.2527 | F12: =Datasets!E57 -> 0.2596 | G12: =Datasets!F57 -> 0.2659 | H12: =Datasets!G57 -> 0.2693 | I12: =Datasets!H57 -> 0.269 | J12: =Datasets!I57 -> 0.2621 | ... CX12: =Datasets!CW57 -> 0.1596
A13: EO00 | B13: Other equipment | C13: =Datasets!B58 -> 0 | D13: =Datasets!C58 -> 0 | E13: =Datasets!D58 -> 0 | F13: =Datasets!E58 -> 0 | G13: =Datasets!F58 -> 0 | H13: =Datasets!G58 -> 0 | I13: =Datasets!H58 -> 0 | J13: =Datasets!I58 -> 0 | ... CX13: =Datasets!CW58 -> 0.1695
A14: ST00 | B14: Structures | C14: =Datasets!B59 -> 0.0237 | D14: =Datasets!C59 -> 0.0237 | E14: =Datasets!D59 -> 0.0237 | F14: =Datasets!E59 -> 0.0237 | G14: =Datasets!F59 -> 0.0237 | H14: =Datasets!G59 -> 0.0237 | I14: =Datasets!H59 -> 0.0237 | J14: =Datasets!I59 -> 0.0237 | ... CX14: =Datasets!CW59 -> 0.0236
A15: SCHC | B15: Commercial and healthcare | C15: =Datasets!B60 -> 0 | D15: =Datasets!C60 -> 0 | E15: =Datasets!D60 -> 0 | F15: =Datasets!E60 -> 0 | G15: =Datasets!F60 -> 0 | H15: =Datasets!G60 -> 0 | I15: =Datasets!H60 -> 0 | J15: =Datasets!I60 -> 0 | ... CX15: =Datasets!CW60 -> 0.0252
A16: IP00 | B16: Intellectual property products | C16: =Datasets!B61 -> 0.16 | D16: =Datasets!C61 -> 0.16 | E16: =Datasets!D61 -> 0.16 | F16: =Datasets!E61 -> 0.16 | G16: =Datasets!F61 -> 0.16 | H16: =Datasets!G61 -> 0.16 | I16: =Datasets!H61 -> 0.16 | J16: =Datasets!I61 -> 0.16 | ... CX16: =Datasets!CW61 -> 0.388

Sheet 2212
A1: 2212 - Natural Gas Distribution
A2: Implied Depreciation Rates for Private Nonresidential Fixed Assets
A3: Updated September 26, 2025
A5: Asset Codes | B5: NIPA Asset Types | C5: 1925 | D5: 1926 | E5: 1927 | F5: 1928 | G5: 1929 | H5: 1930 | I5: 1931 | J5: 1932 | K5: 1933 | L5: 1934 | M5: 1935 | N5: 1936 | O5: 1937 | P5: 1938 | Q5: 1939 | R5: 1940 | S5: 1941 | T5: 1942 | U5: 1943 | V5: 1944 | W5: 1945 | X5: 1946 | Y5: 1947 | Z5: 1948 | AA5: 1949 | AB5: 1950 | AC5: 1951 | AD5: 1952 | AE5: 1953 | AF5: 1954 | AG5: 1955 | AH5: 1956 | AI5: 1957 | AJ5: 1958 | AK5: 1959 | AL5: 1960 | AM5: 1961 | AN5: 1962 | AO5: 1963 | AP5: 1964 | AQ5: 1965 | AR5: 1966 | AS5: 1967 | AT5: 1968 | AU5: 1969 | AV5: 1970 | AW5: 1971 | AX5: 1972 | AY5: 1973 | AZ5: 1974 | BA5: 1975 | BB5: 1976 | BC5: 1977 | BD5: 1978 | BE5: 1979 | BF5: 1980 | BG5: 1981 | BH5: 1982 | BI5: 1983 | BJ5: 1984 | BK5: 1985 | BL5: 1986 | BM5: 1987 | BN5: 1988 | BO5: 1989 | BP5: 1990 | BQ5: 1991 | BR5: 1992 | BS5: 1993 | BT5: 1994 | BU5: 1995 | BV5: 1996 | BW5: 1997 | BX5: 1998 | BY5: 1999 | BZ5: 2000 | CA5: 2001 | CB5: 2002 | CC5: 2003 | CD5: 2004 | CE5: 2005 | CF5: 2006 | CG5: 2007 | CH5: 2008 | CI5: 2009 | CJ5: 2010 | CK5: 2011 | CL5: 2012 | CM5: 2013 | CN5: 2014 | CO5: 2015 | CP5: 2016 | CQ5: 2017 | CR5: 2018 | CS5: 2019 | CT5: 2020 | CU5: 2021 | CV5: 2022 | CW5: 2023 | CX5: 2024
A7: ES00 | B7: Equipment, structures, and intellectual property products | C7: =Datasets!B62 -> 0.0259 | D7: =Datasets!C62 -> 0.0263 | E7: =Datasets!D62 -> 0.0267 | F7: =Datasets!E62 -> 0.027 | G7: =Datasets!F62 -> 0.0271 | H7: =Datasets!G62 -> 0.0271 | I7: =Datasets!H62 -> 0.0269 | J7: =Datasets!I62 -> 0.0267 | ... CX7: =Datasets!CW62 -> 0.0481
A8: EQ00 | B8: Equipment | C8: =Datasets!B63 -> 0.1051 | D8: =Datasets!C63 -> 0.1078 | E8: =Datasets!D63 -> 0.1075 | F8: =Datasets!E63 -> 0.1061 | G8: =Datasets!F63 -> 0.1051 | H8: =Datasets!G63 -> 0.1054 | I8: =Datasets!H63 -> 0.1055 | J8: =Datasets!I63 -> 0.1052 | ... CX8: =Datasets!CW63 -> 0.1044
A9: EP00 | B9: Information | C9: =Datasets!B64 -> 0.135 | D9: =Datasets!C64 -> 0.135 | E9: =Datasets!D64 -> 0.135 | F9: =Datasets!E64 -> 0.135 | G9: =Datasets!F64 -> 0.135 | H9: =Datasets!G64 -> 0.135 | I9: =Datasets!H64 -> 0.135 | J9: =Datasets!I64 -> 0.135 | ... CX9: =Datasets!CW64 -> 0.1464
A10: EP11 | B10: Computers | C10: =Datasets!B65 -> 0 | D10: =Datasets!C65 -> 0 | E10: =Datasets!D65 -> 0 | F10: =Datasets!E65 -> 0 | G10: =Datasets!F65 -> 0 | H10: =Datasets!G65 -> 0 | I10: =Datasets!H65 -> 0 | J10: =Datasets!I65 -> 0 | ... CX10: =Datasets!CW65 -> 0.3373
A11: EI00 | B11: Industrial | C11: =Datasets!B66 -> 0.0994 | D11: =Datasets!C66 -> 0.0999 | E11: =Datasets!D66 -> 0.1003 | F11: =Datasets!E66 -> 0.0992 | G11: =Datasets!F66 -> 0.0983 | H11: =Datasets!G66 -> 0.0983 | I11: =Datasets!H66 -> 0.0982 | J11: =Datasets!I66 -> 0.098 | ... CX11: =Datasets!CW66 -> 0.062
A12: ET00 | B12: Transportation | C12: =Datasets!B67 -> 0.2387 | D12: =Datasets!C67 -> 0.2522 | E12: =Datasets!D67 -> 0.2527 | F12: =Datasets!E67 -> 0.2596 | G12: =Datasets!F67 -> 0.2659 | H12: =Datasets!G67 -> 0.2693 | I12: =Datasets!H67 -> 0.269 | J12: =Datasets!I67 -> 0.2621 | ... CX12: =Datasets!CW67 -> 0.1489
A13: EO00 | B13: Other equipment | C13: =Datasets!B68 -> 0.1179 | D13: =Datasets!C68 -> 0.1179 | E13: =Datasets!D68 -> 0.1179 | F13: =Datasets!E68 -> 0.1179 | G13: =Datasets!F68 -> 0.1179 | H13: =Datasets!G68 -> 0.15 | I13: =Datasets!H68 -> 0.15 | J13: =Datasets!I68 -> 0.15 | ... CX13: =Datasets!CW68 -> 0.1496
A14: ST00 | B14: Structures | C14: =Datasets!B69 -> 0.0237 | D14: =Datasets!C69 -> 0.0237 | E14: =Datasets!D69 -> 0.0237 | F14: =Datasets!E69 -> 0.0237 | G14: =Datasets!F69 -> 0.0237 | H14: =Datasets!G69 -> 0.0237 | I14: =Datasets!H69 -> 0.0237 | J14: =Datasets!I69 -> 0.0237 | ... CX14: =Datasets!CW69 -> 0.0242
A15: SCHC | B15: Commercial and healthcare | C15: =Datasets!B70 -> 0.0262 | D15: =Datasets!C70 -> 0.0262 | E15: =Datasets!D70 -> 0.0262 | F15: =Datasets!E70 -> 0.0262 | G15: =Datasets!F70 -> 0.0262 | H15: =Datasets!G70 -> 0.0262 | I15: =Datasets!H70 -> 0.0262 | J15: =Datasets!I70 -> 0.0262 | ... CX15: =Datasets!CW70 -> 0.0248
A16: IP00 | B16: Intellectual property products | C16: =Datasets!B71 -> 0.16 | D16: =Datasets!C71 -> 0.16 | E16: =Datasets!D71 -> 0.16 | F16: =Datasets!E71 -> 0.16 | G16: =Datasets!F71 -> 0.16 | H16: =Datasets!G71 -> 0.16 | I16: =Datasets!H71 -> 0.16 | J16: =Datasets!I71 -> 0.16 | ... CX16: =Datasets!CW71 -> 0.3985

Sheet 2213
A1: 2213 - Water, Sewage, and Other Systems
A2: Implied Depreciation Rates for Private Nonresidential Fixed Assets
A3: Updated September 26, 2025
A5: Asset Codes | B5: NIPA Asset Types | C5: 1925 | D5: 1926 | E5: 1927 | F5: 1928 | G5: 1929 | H5: 1930 | I5: 1931 | J5: 1932 | K5: 1933 | L5: 1934 | M5: 1935 | N5: 1936 | O5: 1937 | P5: 1938 | Q5: 1939 | R5: 1940 | S5: 1941 | T5: 1942 | U5: 1943 | V5: 1944 | W5: 1945 | X5: 1946 | Y5: 1947 | Z5: 1948 | AA5: 1949 | AB5: 1950 | AC5: 1951 | AD5: 1952 | AE5: 1953 | AF5: 1954 | AG5: 1955 | AH5: 1956 | AI5: 1957 | AJ5: 1958 | AK5: 1959 | AL5: 1960 | AM5: 1961 | AN5: 1962 | AO5: 1963 | AP5: 1964 | AQ5: 1965 | AR5: 1966 | AS5: 1967 | AT5: 1968 | AU5: 1969 | AV5: 1970 | AW5: 1971 | AX5: 1972 | AY5: 1973 | AZ5: 1974 | BA5: 1975 | BB5: 1976 | BC5: 1977 | BD5: 1978 | BE5: 1979 | BF5: 1980 | BG5: 1981 | BH5: 1982 | BI5: 1983 | BJ5: 1984 | BK5: 1985 | BL5: 1986 | BM5: 1987 | BN5: 1988 | BO5: 1989 | BP5: 1990 | BQ5: 1991 | BR5: 1992 | BS5: 1993 | BT5: 1994 | BU5: 1995 | BV5: 1996 | BW5: 1997 | BX5: 1998 | BY5: 1999 | BZ5: 2000 | CA5: 2001 | CB5: 2002 | CC5: 2003 | CD5: 2004 | CE5: 2005 | CF5: 2006 | CG5: 2007 | CH5: 2008 | CI5: 2009 | CJ5: 2010 | CK5: 2011 | CL5: 2012 | CM5: 2013 | CN5: 2014 | CO5: 2015 | CP5: 2016 | CQ5: 2017 | CR5: 2018 | CS5: 2019 | CT5: 2020 | CU5: 2021 | CV5: 2022 | CW5: 2023 | CX5: 2024
A7: ES00 | B7: Equipment, structures, and intellectual property products | C7: =Datasets!B72 -> 0.0251 | D7: =Datasets!C72 -> 0.026 | E7: =Datasets!D72 -> 0.0264 | F7: =Datasets!E72 -> 0.0266 | G7: =Datasets!F72 -> 0.0269 | H7: =Datasets!G72 -> 0.0273 | I7: =Datasets!H72 -> 0.0275 | J7: =Datasets!I72 -> 0.0275 | ... CX7: =Datasets!CW72 -> 0.066
A8: EQ00 | B8: Equipment | C8: =Datasets!B73 -> 0.0574 | D8: =Datasets!C73 -> 0.0607 | E8: =Datasets!D73 -> 0.0609 | F8: =Datasets!E73 -> 0.0614 | G8: =Datasets!F73 -> 0.0616 | H8: =Datasets!G73 -> 0.0615 | I8: =Datasets!H73 -> 0.0614 | J8: =Datasets!I73 -> 0.0612 | ... CX8: =Datasets!CW73 -> 0.1447
A9: EP00 | B9: Information | C9: =Datasets!B74 -> 0.135 | D9: =Datasets!C74 -> 0.135 | E9: =Datasets!D74 -> 0.135 | F9: =Datasets!E74 -> 0.135 | G9: =Datasets!F74 -> 0.135 | H9: =Datasets!G74 -> 0.135 | I9: =Datasets!H74 -> 0.135 | J9: =Datasets!I74 -> 0.135 | ... CX9: =Datasets!CW74 -> 0.1563
A10: EP11 | B10: Computers | C10: =Datasets!B75 -> 0 | D10: =Datasets!C75 -> 0 | E10: =Datasets!D75 -> 0 | F10: =Datasets!E75 -> 0 | G10: =Datasets!F75 -> 0 | H10: =Datasets!G75 -> 0 | I10: =Datasets!H75 -> 0 | J10: =Datasets!I75 -> 0 | ... CX10: =Datasets!CW75 -> 0.3322
A11: EI00 | B11: Industrial | C11: =Datasets!B76 -> 0.0526 | D11: =Datasets!C76 -> 0.0525 | E11: =Datasets!D76 -> 0.0525 | F11: =Datasets!E76 -> 0.0525 | G11: =Datasets!F76 -> 0.0525 | H11: =Datasets!G76 -> 0.0524 | I11: =Datasets!H76 -> 0.0525 | J11: =Datasets!I76 -> 0.0525 | ... CX11: =Datasets!CW76 -> 0.0844
A12: ET00 | B12: Transportation | C12: =Datasets!B77 -> 0.2387 | D12: =Datasets!C77 -> 0.2522 | E12: =Datasets!D77 -> 0.2527 | F12: =Datasets!E77 -> 0.2596 | G12: =Datasets!F77 -> 0.2659 | H12: =Datasets!G77 -> 0.2693 | I12: =Datasets!H77 -> 0.269 | J12: =Datasets!I77 -> 0.2621 | ... CX12: =Datasets!CW77 -> 0.1919
A13: EO00 | B13: Other equipment | C13: =Datasets!B78 -> 0 | D13: =Datasets!C78 -> 0 | E13: =Datasets!D78 -> 0 | F13: =Datasets!E78 -> 0 | G13: =Datasets!F78 -> 0 | H13: =Datasets!G78 -> 0.15 | I13: =Datasets!H78 -> 0.15 | J13: =Datasets!I78 -> 0.15 | ... CX13: =Datasets!CW78 -> 0.1493
A14: ST00 | B14: Structures | C14: =Datasets!B79 -> 0.0225 | D14: =Datasets!C79 -> 0.0225 | E14: =Datasets!D79 -> 0.0225 | F14: =Datasets!E79 -> 0.0225 | G14: =Datasets!F79 -> 0.0225 | H14: =Datasets!G79 -> 0.0225 | I14: =Datasets!H79 -> 0.0225 | J14: =Datasets!I79 -> 0.0225 | ... CX14: =Datasets!CW79 -> 0.0233
A15: SCHC | B15: Commercial and healthcare | C15: =Datasets!B80 -> 0.0247 | D15: =Datasets!C80 -> 0.0247 | E15: =Datasets!D80 -> 0.0247 | F15: =Datasets!E80 -> 0.0247 | G15: =Datasets!F80 -> 0.0247 | H15: =Datasets!G80 -> 0.0247 | I15: =Datasets!H80 -> 0.0247 | J15: =Datasets!I80 -> 0.0247 | ... CX15: =Datasets!CW80 -> 0.0253
A16: IP00 | B16: Intellectual property products | C16: =Datasets!B81 -> 0.16 | D16: =Datasets!C81 -> 0.16 | E16: =Datasets!D81 -> 0.16 | F16: =Datasets!E81 -> 0.16 | G16: =Datasets!F81 -> 0.16 | H16: =Datasets!G81 -> 0.16 | I16: =Datasets!H81 -> 0.16 | J16: =Datasets!I81 -> 0.16 | ... CX16: =Datasets!CW81 -> 0.4189

Sheet 2300
A1: 2300 - Construction
A2: Implied Depreciation Rates for Private Nonresidential Fixed Assets
A3: Updated September 26, 2025
A5: Asset Codes | B5: NIPA Asset Types | C5: 1925 | D5: 1926 | E5: 1927 | F5: 1928 | G5: 1929 | H5: 1930 | I5: 1931 | J5: 1932 | K5: 1933 | L5: 1934 | M5: 1935 | N5: 1936 | O5: 1937 | P5: 1938 | Q5: 1939 | R5: 1940 | S5: 1941 | T5: 1942 | U5: 1943 | V5: 1944 | W5: 1945 | X5: 1946 | Y5: 1947 | Z5: 1948 | AA5: 1949 | AB5: 1950 | AC5: 1951 | AD5: 1952 | AE5: 1953 | AF5: 1954 | AG5: 1955 | AH5: 1956 | AI5: 1957 | AJ5: 1958 | AK5: 1959 | AL5: 1960 | AM5: 1961 | AN5: 1962 | AO5: 1963 | AP5: 1964 | AQ5: 1965 | AR5: 1966 | AS5: 1967 | AT5: 1968 | AU5: 1969 | AV5: 1970 | AW5: 1971 | AX5: 1972 | AY5: 1973 | AZ5: 1974 | BA5: 1975 | BB5: 1976 | BC5: 1977 | BD5: 1978 | BE5: 1979 | BF5: 1980 | BG5: 1981 | BH5: 1982 | BI5: 1983 | BJ5: 1984 | BK5: 1985 | BL5: 1986 | BM5: 1987 | BN5: 1988 | BO5: 1989 | BP5: 1990 | BQ5: 1991 | BR5: 1992 | BS5: 1993 | BT5: 1994 | BU5: 1995 | BV5: 1996 | BW5: 1997 | BX5: 1998 | BY5: 1999 | BZ5: 2000 | CA5: 2001 | CB5: 2002 | CC5: 2003 | CD5: 2004 | CE5: 2005 | CF5: 2006 | CG5: 2007 | CH5: 2008 | CI5: 2009 | CJ5: 2010 | CK5: 2011 | CL5: 2012 | CM5: 2013 | CN5: 2014 | CO5: 2015 | CP5: 2016 | CQ5: 2017 | CR5: 2018 | CS5: 2019 | CT5: 2020 | CU5: 2021 | CV5: 2022 | CW5: 2023 | CX5: 2024
A7: ES00 | B7: Equipment, structures, and intellectual property products | C7: =Datasets!B82 -> 0.1525 | D7: =Datasets!C82 -> 0.1518 | E7: =Datasets!D82 -> 0.15 | F7: =Datasets!E82 -> 0.1492 | G7: =Datasets!F82 -> 0.1483 | H7: =Datasets!G82 -> 0.147 | I7: =Datasets!H82 -> 0.1459 | J7: =Datasets!I82 -> 0.1444 | ... CX7: =Datasets!CW82 -> 0.1348
A8: EQ00 | B8: Equipment | C8: =Datasets!B83 -> 0.1559 | D8: =Datasets!C83 -> 0.1555 | E8: =Datasets!D83 -> 0.1541 | F8: =Datasets!E83 -> 0.1534 | G8: =Datasets!F83 -> 0.1528 | H8: =Datasets!G83 -> 0.1522 | I8: =Datasets!H83 -> 0.1517 | J8: =Datasets!I83 -> 0.1511 | ... CX8: =Datasets!CW83 -> 0.1636
A9: EP00 | B9: Information | C9: =Datasets!B84 -> 0 | D9: =Datasets!C84 -> 0 | E9: =Datasets!D84 -> 0 | F9: =Datasets!E84 -> 0 | G9: =Datasets!F84 -> 0 | H9: =Datasets!G84 -> 0 | I9: =Datasets!H84 -> 0 | J9: =Datasets!I84 -> 0 | ... CX9: =Datasets!CW84 -> 0.2075
A10: EP11 | B10: Computers | C10: =Datasets!B85 -> 0 | D10: =Datasets!C85 -> 0 | E10: =Datasets!D85 -> 0 | F10: =Datasets!E85 -> 0 | G10: =Datasets!F85 -> 0 | H10: =Datasets!G85 -> 0 | I10: =Datasets!H85 -> 0 | J10: =Datasets!I85 -> 0 | ... CX10: =Datasets!CW85 -> 0.3396
A11: EI00 | B11: Industrial | C11: =Datasets!B86 -> 0.1642 | D11: =Datasets!C86 -> 0.1543 | E11: =Datasets!D86 -> 0.1458 | F11: =Datasets!E86 -> 0.141 | G11: =Datasets!F86 -> 0.1376 | H11: =Datasets!G86 -> 0.1347 | I11: =Datasets!H86 -> 0.1327 | J11: =Datasets!I86 -> 0.1304 | ... CX11: =Datasets!CW86 -> 0.0995
A12: ET00 | B12: Transportation | C12: =Datasets!B87 -> 0.2387 | D12: =Datasets!C87 -> 0.2522 | E12: =Datasets!D87 -> 0.2527 | F12: =Datasets!E87 -> 0.2596 | G12: =Datasets!F87 -> 0.2659 | H12: =Datasets!G87 -> 0.2693 | I12: =Datasets!H87 -> 0.269 | J12: =Datasets!I87 -> 0.2621 | ... CX12: =Datasets!CW87 -> 0.1883
A13: EO00 | B13: Other equipment | C13: =Datasets!B88 -> 0.1519 | D13: =Datasets!C88 -> 0.1521 | E13: =Datasets!D88 -> 0.1523 | F13: =Datasets!E88 -> 0.1525 | G13: =Datasets!F88 -> 0.1526 | H13: =Datasets!G88 -> 0.1527 | I13: =Datasets!H88 -> 0.1528 | J13: =Datasets!I88 -> 0.1529 | ... CX13: =Datasets!CW88 -> 0.1545
A14: ST00 | B14: Structures | C14: =Datasets!B89 -> 0.0239 | D14: =Datasets!C89 -> 0.0239 | E14: =Datasets!D89 -> 0.0239 | F14: =Datasets!E89 -> 0.024 | G14: =Datasets!F89 -> 0.024 | H14: =Datasets!G89 -> 0.024 | I14: =Datasets!H89 -> 0.024 | J14: =Datasets!I89 -> 0.024 | ... CX14: =Datasets!CW89 -> 0.0259
A15: SCHC | B15: Commercial and healthcare | C15: =Datasets!B90 -> 0.0245 | D15: =Datasets!C90 -> 0.0244 | E15: =Datasets!D90 -> 0.0243 | F15: =Datasets!E90 -> 0.0243 | G15: =Datasets!F90 -> 0.0244 | H15: =Datasets!G90 -> 0.0244 | I15: =Datasets!H90 -> 0.0244 | J15: =Datasets!I90 -> 0.0244 | ... CX15: =Datasets!CW90 -> 0.0246
A16: IP00 | B16: Intellectual property products | C16: =Datasets!B91 -> 0.16 | D16: =Datasets!C91 -> 0.16 | E16: =Datasets!D91 -> 0.16 | F16: =Datasets!E91 -> 0.16 | G16: =Datasets!F91 -> 0.16 | H16: =Datasets!G91 -> 0.16 | I16: =Datasets!H91 -> 0.16 | J16: =Datasets!I91 -> 0.16 | ... CX16: =Datasets!CW91 -> 0.2855

Sheet 3210
A1: 3210 - Wood Products
A2: Implied Depreciation Rates for Private Nonresidential Fixed Assets
A3: Updated September 26, 2025
A5: Asset Codes | B5: NIPA Asset Types | C5: 1925 | D5: 1926 | E5: 1927 | F5: 1928 | G5: 1929 | H5: 1930 | I5: 1931 | J5: 1932 | K5: 1933 | L5: 1934 | M5: 1935 | N5: 1936 | O5: 1937 | P5: 1938 | Q5: 1939 | R5: 1940 | S5: 1941 | T5: 1942 | U5: 1943 | V5: 1944 | W5: 1945 | X5: 1946 | Y5: 1947 | Z5: 1948 | AA5: 1949 | AB5: 1950 | AC5: 1951 | AD5: 1952 | AE5: 1953 | AF5: 1954 | AG5: 1955 | AH5: 1956 | AI5: 1957 | AJ5: 1958 | AK5: 1959 | AL5: 1960 | AM5: 1961 | AN5: 1962 | AO5: 1963 | AP5: 1964 | AQ5: 1965 | AR5: 1966 | AS5: 1967 | AT5: 1968 | AU5: 1969 | AV5: 1970 | AW5: 1971 | AX5: 1972 | AY5: 1973 | AZ5: 1974 | BA5: 1975 | BB5: 1976 | BC5: 1977 | BD5: 1978 | BE5: 1979 | BF5: 1980 | BG5: 1981 | BH5: 1982 | BI5: 1983 | BJ5: 1984 | BK5: 1985 | BL5: 1986 | BM5: 1987 | BN5: 1988 | BO5: 1989 | BP5: 1990 | BQ5: 1991 | BR5: 1992 | BS5: 1993 | BT5: 1994 | BU5: 1995 | BV5: 1996 | BW5: 1997 | BX5: 1998 | BY5: 1999 | BZ5: 2000 | CA5: 2001 | CB5: 2002 | CC5: 2003 | CD5: 2004 | CE5: 2005 | CF5: 2006 | CG5: 2007 | CH5: 2008 | CI5: 2009 | CJ5: 2010 | CK5: 2011 | CL5: 2012 | CM5: 2013 | CN5: 2014 | CO5: 2015 | CP5: 2016 | CQ5: 2017 | CR5: 2018 | CS5: 2019 | CT5: 2020 | CU5: 2021 | CV5: 2022 | CW5: 2023 | CX5: 2024
A7: ES00 | B7: Equipment, structures, and intellectual property products | C7: =Datasets!B92 -> 0.0637 | D7: =Datasets!C92 -> 0.0675 | E7: =Datasets!D92 -> 0.0688 | F7: =Datasets!E92 -> 0.0687 | G7: =Datasets!F92 -> 0.0683 | H7: =Datasets!G92 -> 0.0672 | I7: =Datasets!H92 -> 0.0655 | J7: =Datasets!I92 -> 0.0639 | ... CX7: =Datasets!CW92 -> 0.0962
A8: EQ00 | B8: Equipment | C8: =Datasets!B93 -> 0.1393 | D8: =Datasets!C93 -> 0.1407 | E8: =Datasets!D93 -> 0.1409 | F8: =Datasets!E93 -> 0.1414 | G8: =Datasets!F93 -> 0.1417 | H8: =Datasets!G93 -> 0.1419 | I8: =Datasets!H93 -> 0.1421 | J8: =Datasets!I93 -> 0.142 | ... CX8: =Datasets!CW93 -> 0.1416
A9: EP00 | B9: Information | C9: =Datasets!B94 -> 0.135 | D9: =Datasets!C94 -> 0.135 | E9: =Datasets!D94 -> 0.135 | F9: =Datasets!E94 -> 0.135 | G9: =Datasets!F94 -> 0.135 | H9: =Datasets!G94 -> 0.135 | I9: =Datasets!H94 -> 0.135 | J9: =Datasets!I94 -> 0.135 | ... CX9: =Datasets!CW94 -> 0.1989
A10: EP11 | B10: Computers | C10: =Datasets!B95 -> 0 | D10: =Datasets!C95 -> 0 | E10: =Datasets!D95 -> 0 | F10: =Datasets!E95 -> 0 | G10: =Datasets!F95 -> 0 | H10: =Datasets!G95 -> 0 | I10: =Datasets!H95 -> 0 | J10: =Datasets!I95 -> 0 | ... CX10: =Datasets!CW95 -> 0.3382
A11: EI00 | B11: Industrial | C11: =Datasets!B96 -> 0.1371 | D11: =Datasets!C96 -> 0.1371 | E11: =Datasets!D96 -> 0.1372 | F11: =Datasets!E96 -> 0.1372 | G11: =Datasets!F96 -> 0.1371 | H11: =Datasets!G96 -> 0.1371 | I11: =Datasets!H96 -> 0.137 | J11: =Datasets!I96 -> 0.1369 | ... CX11: =Datasets!CW96 -> 0.1342
A12: ET00 | B12: Transportation | C12: =Datasets!B97 -> 0.2387 | D12: =Datasets!C97 -> 0.2522 | E12: =Datasets!D97 -> 0.2527 | F12: =Datasets!E97 -> 0.2596 | G12: =Datasets!F97 -> 0.2659 | H12: =Datasets!G97 -> 0.2693 | I12: =Datasets!H97 -> 0.269 | J12: =Datasets!I97 -> 0.2621 | ... CX12: =Datasets!CW97 -> 0.1922
A13: EO00 | B13: Other equipment | C13: =Datasets!B98 -> 0 | D13: =Datasets!C98 -> 0 | E13: =Datasets!D98 -> 0 | F13: =Datasets!E98 -> 0 | G13: =Datasets!F98 -> 0 | H13: =Datasets!G98 -> 0 | I13: =Datasets!H98 -> 0 | J13: =Datasets!I98 -> 0 | ... CX13: =Datasets!CW98 -> 0.1511
A14: ST00 | B14: Structures | C14: =Datasets!B99 -> 0.0313 | D14: =Datasets!C99 -> 0.0313 | E14: =Datasets!D99 -> 0.0313 | F14: =Datasets!E99 -> 0.0313 | G14: =Datasets!F99 -> 0.0313 | H14: =Datasets!G99 -> 0.0313 | I14: =Datasets!H99 -> 0.0313 | J14: =Datasets!I99 -> 0.0313 | ... CX14: =Datasets!CW99 -> 0.0309
A15: SCHC | B15: Commercial and healthcare | C15: =Datasets!B100 -> 0.0247 | D15: =Datasets!C100 -> 0.0247 | E15: =Datasets!D100 -> 0.0247 | F15: =Datasets!E100 -> 0.0247 | G15: =Datasets!F100 -> 0.0247 | H15: =Datasets!G100 -> 0.0247 | I15: =Datasets!H100 -> 0.0247 | J15: =Datasets!I100 -> 0.0247 | ... CX15: =Datasets!CW100 -> 0.0247
A16: IP00 | B16: Intellectual property products | C16: =Datasets!B101 -> 0 | D16: =Datasets!C101 -> 0 | E16: =Datasets!D101 -> 0 | F16: =Datasets!E101 -> 0 | G16: =Datasets!F101 -> 0 | H16: =Datasets!G101 -> 0 | I16: =Datasets!H101 -> 0 | J16: =Datasets!I101 -> 0 | ... CX16: =Datasets!CW101 -> 0.3155

Sheet 3270
A1: 3270 - Nonmetallic Mineral Products
A2: Implied Depreciation Rates for Private Nonresidential Fixed Assets
A3: Updated September 26, 2025
A5: Asset Codes | B5: NIPA Asset Types | C5: 1925 | D5: 1926 | E5: 1927 | F5: 1928 | G5: 1929 | H5: 1930 | I5: 1931 | J5: 1932 | K5: 1933 | L5: 1934 | M5: 1935 | N5: 1936 | O5: 1937 | P5: 1938 | Q5: 1939 | R5: 1940 | S5: 1941 | T5: 1942 | U5: 1943 | V5: 1944 | W5: 1945 | X5: 1946 | Y5: 1947 | Z5: 1948 | AA5: 1949 | AB5: 1950 | AC5: 1951 | AD5: 1952 | AE5: 1953 | AF5: 1954 | AG5: 1955 | AH5: 1956 | AI5: 1957 | AJ5: 1958 | AK5: 1959 | AL5: 1960 | AM5: 1961 | AN5: 1962 | AO5: 1963 | AP5: 1964 | AQ5: 1965 | AR5: 1966 | AS5: 1967 | AT5: 1968 | AU5: 1969 | AV5: 1970 | AW5: 1971 | AX5: 1972 | AY5: 1973 | AZ5: 1974 | BA5: 1975 | BB5: 1976 | BC5: 1977 | BD5: 1978 | BE5: 1979 | BF5: 1980 | BG5: 1981 | BH5: 1982 | BI5: 1983 | BJ5: 1984 | BK5: 1985 | BL5: 1986 | BM5: 1987 | BN5: 1988 | BO5: 1989 | BP5: 1990 | BQ5: 1991 | BR5: 1992 | BS5: 1993 | BT5: 1994 | BU5: 1995 | BV5: 1996 | BW5: 1997 | BX5: 1998 | BY5: 1999 | BZ5: 2000 | CA5: 2001 | CB5: 2002 | CC5: 2003 | CD5: 2004 | CE5: 2005 | CF5: 2006 | CG5: 2007 | CH5: 2008 | CI5: 2009 | CJ5: 2010 | CK5: 2011 | CL5: 2012 | CM5: 2013 | CN5: 2014 | CO5: 2015 | CP5: 2016 | CQ5: 2017 | CR5: 2018 | CS5: 2019 | CT5: 2020 | CU5: 2021 | CV5: 2022 | CW5: 2023 | CX5: 2024
A7: ES00 | B7: Equipment, structures, and intellectual property products | C7: =Datasets!B102 -> 0.0397 | D7: =Datasets!C102 -> 0.0411 | E7: =Datasets!D102 -> 0.0418 | F7: =Datasets!E102 -> 0.0422 | G7: =Datasets!F102 -> 0.0427 | H7: =Datasets!G102 -> 0.0432 | I7: =Datasets!H102 -> 0.0436 | J7: =Datasets!I102 -> 0.0437 | ... CX7: =Datasets!CW102 -> 0.098
A8: EQ00 | B8: Equipment | C8: =Datasets!B103 -> 0.0915 | D8: =Datasets!C103 -> 0.0934 | E8: =Datasets!D103 -> 0.0935 | F8: =Datasets!E103 -> 0.0939 | G8: =Datasets!F103 -> 0.0942 | H8: =Datasets!G103 -> 0.0942 | I8: =Datasets!H103 -> 0.0941 | J8: =Datasets!I103 -> 0.0939 | ... CX8: =Datasets!CW103 -> 0.1119
A9: EP00 | B9: Information | C9: =Datasets!B104 -> 0.135 | D9: =Datasets!C104 -> 0.135 | E9: =Datasets!D104 -> 0.135 | F9: =Datasets!E104 -> 0.135 | G9: =Datasets!F104 -> 0.135 | H9: =Datasets!G104 -> 0.135 | I9: =Datasets!H104 -> 0.135 | J9: =Datasets!I104 -> 0.135 | ... CX9: =Datasets!CW104 -> 0.1419
A10: EP11 | B10: Computers | C10: =Datasets!B105 -> 0 | D10: =Datasets!C105 -> 0 | E10: =Datasets!D105 -> 0 | F10: =Datasets!E105 -> 0 | G10: =Datasets!F105 -> 0 | H10: =Datasets!G105 -> 0 | I10: =Datasets!H105 -> 0 | J10: =Datasets!I105 -> 0 | ... CX10: =Datasets!CW105 -> 0.339
A11: EI00 | B11: Industrial | C11: =Datasets!B106 -> 0.089 | D11: =Datasets!C106 -> 0.089 | E11: =Datasets!D106 -> 0.0889 | F11: =Datasets!E106 -> 0.089 | G11: =Datasets!F106 -> 0.0891 | H11: =Datasets!G106 -> 0.0892 | I11: =Datasets!H106 -> 0.0893 | J11: =Datasets!I106 -> 0.0892 | ... CX11: =Datasets!CW106 -> 0.0901
A12: ET00 | B12: Transportation | C12: =Datasets!B107 -> 0.2387 | D12: =Datasets!C107 -> 0.2522 | E12: =Datasets!D107 -> 0.2527 | F12: =Datasets!E107 -> 0.2596 | G12: =Datasets!F107 -> 0.2659 | H12: =Datasets!G107 -> 0.2693 | I12: =Datasets!H107 -> 0.269 | J12: =Datasets!I107 -> 0.2621 | ... CX12: =Datasets!CW107 -> 0.1857
A13: EO00 | B13: Other equipment | C13: =Datasets!B108 -> 0 | D13: =Datasets!C108 -> 0 | E13: =Datasets!D108 -> 0 | F13: =Datasets!E108 -> 0 | G13: =Datasets!F108 -> 0.1179 | H13: =Datasets!G108 -> 0.1179 | I13: =Datasets!H108 -> 0.1179 | J13: =Datasets!I108 -> 0.1179 | ... CX13: =Datasets!CW108 -> 0.1542
A14: ST00 | B14: Structures | C14: =Datasets!B109 -> 0.0314 | D14: =Datasets!C109 -> 0.0313 | E14: =Datasets!D109 -> 0.0313 | F14: =Datasets!E109 -> 0.0313 | G14: =Datasets!F109 -> 0.0313 | H14: =Datasets!G109 -> 0.0313 | I14: =Datasets!H109 -> 0.0313 | J14: =Datasets!I109 -> 0.0313 | ... CX14: =Datasets!CW109 -> 0.0312
A15: SCHC | B15: Commercial and healthcare | C15: =Datasets!B110 -> 0.0247 | D15: =Datasets!C110 -> 0.0247 | E15: =Datasets!D110 -> 0.0247 | F15: =Datasets!E110 -> 0.0247 | G15: =Datasets!F110 -> 0.0247 | H15: =Datasets!G110 -> 0.0247 | I15: =Datasets!H110 -> 0.0247 | J15: =Datasets!I110 -> 0.0247 | ... CX15: =Datasets!CW110 -> 0.0244
A16: IP00 | B16: Intellectual property products | C16: =Datasets!B111 -> 0.16 | D16: =Datasets!C111 -> 0.16 | E16: =Datasets!D111 -> 0.16 | F16: =Datasets!E111 -> 0.16 | G16: =Datasets!F111 -> 0.16 | H16: =Datasets!G111 -> 0.16 | I16: =Datasets!H111 -> 0.16 | J16: =Datasets!I111 -> 0.16 | ... CX16: =Datasets!CW111 -> 0.1672

Sheet 3310
A1: 3310 - Primary Metals
A2: Implied Depreciation Rates for Private Nonresidential Fixed Assets
A3: Updated September 26, 2025
A5: Asset Codes | B5: NIPA Asset Types | C5: 1925 | D5: 1926 | E5: 1927 | F5: 1928 | G5: 1929 | H5: 1930 | I5: 1931 | J5: 1932 | K5: 1933 | L5: 1934 | M5: 1935 | N5: 1936 | O5: 1937 | P5: 1938 | Q5: 1939 | R5: 1940 | S5: 1941 | T5: 1942 | U5: 1943 | V5: 1944 | W5: 1945 | X5: 1946 | Y5: 1947 | Z5: 1948 | AA5: 1949 | AB5: 1950 | AC5: 1951 | AD5: 1952 | AE5: 1953 | AF5: 1954 | AG5: 1955 | AH5: 1956 | AI5: 1957 | AJ5: 1958 | AK5: 1959 | AL5: 1960 | AM5: 1961 | AN5: 1962 | AO5: 1963 | AP5: 1964 | AQ5: 1965 | AR5: 1966 | AS5: 1967 | AT5: 1968 | AU5: 1969 | AV5: 1970 | AW5: 1971 | AX5: 1972 | AY5: 1973 | AZ5: 1974 | BA5: 1975 | BB5: 1976 | BC5: 1977 | BD5: 1978 | BE5: 1979 | BF5: 1980 | BG5: 1981 | BH5: 1982 | BI5: 1983 | BJ5: 1984 | BK5: 1985 | BL5: 1986 | BM5: 1987 | BN5: 1988 | BO5: 1989 | BP5: 1990 | BQ5: 1991 | BR5: 1992 | BS5: 1993 | BT5: 1994 | BU5: 1995 | BV5: 1996 | BW5: 1997 | BX5: 1998 | BY5: 1999 | BZ5: 2000 | CA5: 2001 | CB5: 2002 | CC5: 2003 | CD5: 2004 | CE5: 2005 | CF5: 2006 | CG5: 2007 | CH5: 2008 | CI5: 2009 | CJ5: 2010 | CK5: 2011 | CL5: 2012 | CM5: 2013 | CN5: 2014 | CO5: 2015 | CP5: 2016 | CQ5: 2017 | CR5: 2018 | CS5: 2019 | CT5: 2020 | CU5: 2021 | CV5: 2022 | CW5: 2023 | CX5: 2024
A7: ES00 | B7: Equipment, structures, and intellectual property products | C7: =Datasets!B112 -> 0.0463 | D7: =Datasets!C112 -> 0.046 | E7: =Datasets!D112 -> 0.0453 | F7: =Datasets!E112 -> 0.0447 | G7: =Datasets!F112 -> 0.0442 | H7: =Datasets!G112 -> 0.0439 | I7: =Datasets!H112 -> 0.0436 | J7: =Datasets!I112 -> 0.0434 | ... CX7: =Datasets!CW112 -> 0.0697
A8: EQ00 | B8: Equipment | C8: =Datasets!B113 -> 0.0698 | D8: =Datasets!C113 -> 0.0697 | E8: =Datasets!D113 -> 0.0688 | F8: =Datasets!E113 -> 0.0683 | G8: =Datasets!F113 -> 0.0679 | H8: =Datasets!G113 -> 0.0677 | I8: =Datasets!H113 -> 0.0673 | J8: =Datasets!I113 -> 0.0669 | ... CX8: =Datasets!CW113 -> 0.0743
A9: EP00 | B9: Information | C9: =Datasets!B114 -> 0.135 | D9: =Datasets!C114 -> 0.135 | E9: =Datasets!D114 -> 0.135 | F9: =Datasets!E114 -> 0.135 | G9: =Datasets!F114 -> 0.135 | H9: =Datasets!G114 -> 0.135 | I9: =Datasets!H114 -> 0.135 | J9: =Datasets!I114 -> 0.135 | ... CX9: =Datasets!CW114 -> 0.1837
A10: EP11 | B10: Computers | C10: =Datasets!B115 -> 0 | D10: =Datasets!C115 -> 0 | E10: =Datasets!D115 -> 0 | F10: =Datasets!E115 -> 0 | G10: =Datasets!F115 -> 0 | H10: =Datasets!G115 -> 0 | I10: =Datasets!H115 -> 0 | J10: =Datasets!I115 -> 0 | ... CX10: =Datasets!CW115 -> 0.3404
A11: EI00 | B11: Industrial | C11: =Datasets!B116 -> 0.0623 | D11: =Datasets!C116 -> 0.0625 | E11: =Datasets!D116 -> 0.0626 | F11: =Datasets!E116 -> 0.0626 | G11: =Datasets!F116 -> 0.0627 | H11: =Datasets!G116 -> 0.0629 | I11: =Datasets!H116 -> 0.0629 | J11: =Datasets!I116 -> 0.063 | ... CX11: =Datasets!CW116 -> 0.0698
A12: ET00 | B12: Transportation | C12: =Datasets!B117 -> 0.2387 | D12: =Datasets!C117 -> 0.2522 | E12: =Datasets!D117 -> 0.2527 | F12: =Datasets!E117 -> 0.2596 | G12: =Datasets!F117 -> 0.2659 | H12: =Datasets!G117 -> 0.2693 | I12: =Datasets!H117 -> 0.269 | J12: =Datasets!I117 -> 0.2621 | ... CX12: =Datasets!CW117 -> 0.1483
A13: EO00 | B13: Other equipment | C13: =Datasets!B118 -> 0.1179 | D13: =Datasets!C118 -> 0.1179 | E13: =Datasets!D118 -> 0.1179 | F13: =Datasets!E118 -> 0.1179 | G13: =Datasets!F118 -> 0.1179 | H13: =Datasets!G118 -> 0.1179 | I13: =Datasets!H118 -> 0.1179 | J13: =Datasets!I118 -> 0.1179 | ... CX13: =Datasets!CW118 -> 0.1477
A14: ST00 | B14: Structures | C14: =Datasets!B119 -> 0.031 | D14: =Datasets!C119 -> 0.031 | E14: =Datasets!D119 -> 0.031 | F14: =Datasets!E119 -> 0.031 | G14: =Datasets!F119 -> 0.0309 | H14: =Datasets!G119 -> 0.0309 | I14: =Datasets!H119 -> 0.0309 | J14: =Datasets!I119 -> 0.0309 | ... CX14: =Datasets!CW119 -> 0.031
A15: SCHC | B15: Commercial and healthcare | C15: =Datasets!B120 -> 0.0247 | D15: =Datasets!C120 -> 0.0247 | E15: =Datasets!D120 -> 0.0247 | F15: =Datasets!E120 -> 0.0247 | G15: =Datasets!F120 -> 0.0247 | H15: =Datasets!G120 -> 0.0247 | I15: =Datasets!H120 -> 0.0247 | J15: =Datasets!I120 -> 0.0247 | ... CX15: =Datasets!CW120 -> 0.0246
A16: IP00 | B16: Intellectual property products | C16: =Datasets!B121 -> 0.16 | D16: =Datasets!C121 -> 0.16 | E16: =Datasets!D121 -> 0.16 | F16: =Datasets!E121 -> 0.16 | G16: =Datasets!F121 -> 0.16 | H16: =Datasets!G121 -> 0.16 | I16: =Datasets!H121 -> 0.16 | J16: =Datasets!I121 -> 0.16 | ... CX16: =Datasets!CW121 -> 0.1802

Sheet 3320
A1: 3320 - Fabricated Metal Products
A2: Implied Depreciation Rates for Private Nonresidential Fixed Assets
A3: Updated September 26, 2025
A5: Asset Codes | B5: NIPA Asset Types | C5: 1925 | D5: 1926 | E5: 1927 | F5: 1928 | G5: 1929 | H5: 1930 | I5: 1931 | J5: 1932 | K5: 1933 | L5: 1934 | M5: 1935 | N5: 1936 | O5: 1937 | P5: 1938 | Q5: 1939 | R5: 1940 | S5: 1941 | T5: 1942 | U5: 1943 | V5: 1944 | W5: 1945 | X5: 1946 | Y5: 1947 | Z5: 1948 | AA5: 1949 | AB5: 1950 | AC5: 1951 | AD5: 1952 | AE5: 1953 | AF5: 1954 | AG5: 1955 | AH5: 1956 | AI5: 1957 | AJ5: 1958 | AK5: 1959 | AL5: 1960 | AM5: 1961 | AN5: 1962 | AO5: 1963 | AP5: 1964 | AQ5: 1965 | AR5: 1966 | AS5: 1967 | AT5: 1968 | AU5: 1969 | AV5: 1970 | AW5: 1971 | AX5: 1972 | AY5: 1973 | AZ5: 1974 | BA5: 1975 | BB5: 1976 | BC5: 1977 | BD5: 1978 | BE5: 1979 | BF5: 1980 | BG5: 1981 | BH5: 1982 | BI5: 1983 | BJ5: 1984 | BK5: 1985 | BL5: 1986 | BM5: 1987 | BN5: 1988 | BO5: 1989 | BP5: 1990 | BQ5: 1991 | BR5: 1992 | BS5: 1993 | BT5: 1994 | BU5: 1995 | BV5: 1996 | BW5: 1997 | BX5: 1998 | BY5: 1999 | BZ5: 2000 | CA5: 2001 | CB5: 2002 | CC5: 2003 | CD5: 2004 | CE5: 2005 | CF5: 2006 | CG5: 2007 | CH5: 2008 | CI5: 2009 | CJ5: 2010 | CK5: 2011 | CL5: 2012 | CM5: 2013 | CN5: 2014 | CO5: 2015 | CP5: 2016 | CQ5: 2017 | CR5: 2018 | CS5: 2019 | CT5: 2020 | CU5: 2021 | CV5: 2022 | CW5: 2023 | CX5: 2024
A7: ES00 | B7: Equipment, structures, and intellectual property products | C7: =Datasets!B122 -> 0.0463 | D7: =Datasets!C122 -> 0.0493 | E7: =Datasets!D122 -> 0.0502 | F7: =Datasets!E122 -> 0.0511 | G7: =Datasets!F122 -> 0.0519 | H7: =Datasets!G122 -> 0.0525 | I7: =Datasets!H122 -> 0.0532 | J7: =Datasets!I122 -> 0.0535 | ... CX7: =Datasets!CW122 -> 0.0833
A8: EQ00 | B8: Equipment | C8: =Datasets!B123 -> 0.0942 | D8: =Datasets!C123 -> 0.0997 | E8: =Datasets!D123 -> 0.0985 | F8: =Datasets!E123 -> 0.0976 | G8: =Datasets!F123 -> 0.0963 | H8: =Datasets!G123 -> 0.0946 | I8: =Datasets!H123 -> 0.093 | J8: =Datasets!I123 -> 0.0914 | ... CX8: =Datasets!CW123 -> 0.088
A9: EP00 | B9: Information | C9: =Datasets!B124 -> 0.135 | D9: =Datasets!C124 -> 0.135 | E9: =Datasets!D124 -> 0.135 | F9: =Datasets!E124 -> 0.135 | G9: =Datasets!F124 -> 0.135 | H9: =Datasets!G124 -> 0.135 | I9: =Datasets!H124 -> 0.135 | J9: =Datasets!I124 -> 0.135 | ... CX9: =Datasets!CW124 -> 0.1866
A10: EP11 | B10: Computers | C10: =Datasets!B125 -> 0 | D10: =Datasets!C125 -> 0 | E10: =Datasets!D125 -> 0 | F10: =Datasets!E125 -> 0 | G10: =Datasets!F125 -> 0 | H10: =Datasets!G125 -> 0 | I10: =Datasets!H125 -> 0 | J10: =Datasets!I125 -> 0 | ... CX10: =Datasets!CW125 -> 0.3394
A11: EI00 | B11: Industrial | C11: =Datasets!B126 -> 0.0785 | D11: =Datasets!C126 -> 0.0784 | E11: =Datasets!D126 -> 0.0781 | F11: =Datasets!E126 -> 0.0779 | G11: =Datasets!F126 -> 0.0778 | H11: =Datasets!G126 -> 0.0774 | I11: =Datasets!H126 -> 0.077 | J11: =Datasets!I126 -> 0.0767 | ... CX11: =Datasets!CW126 -> 0.0822
A12: ET00 | B12: Transportation | C12: =Datasets!B127 -> 0.2387 | D12: =Datasets!C127 -> 0.2522 | E12: =Datasets!D127 -> 0.2527 | F12: =Datasets!E127 -> 0.2596 | G12: =Datasets!F127 -> 0.2659 | H12: =Datasets!G127 -> 0.2693 | I12: =Datasets!H127 -> 0.269 | J12: =Datasets!I127 -> 0.2621 | ... CX12: =Datasets!CW127 -> 0.1805
A13: EO00 | B13: Other equipment | C13: =Datasets!B128 -> 0.1179 | D13: =Datasets!C128 -> 0.1179 | E13: =Datasets!D128 -> 0.1179 | F13: =Datasets!E128 -> 0.1179 | G13: =Datasets!F128 -> 0.1179 | H13: =Datasets!G128 -> 0.1179 | I13: =Datasets!H128 -> 0.1179 | J13: =Datasets!I128 -> 0.1179 | ... CX13: =Datasets!CW128 -> 0.1457
A14: ST00 | B14: Structures | C14: =Datasets!B129 -> 0.0312 | D14: =Datasets!C129 -> 0.0312 | E14: =Datasets!D129 -> 0.0311 | F14: =Datasets!E129 -> 0.0311 | G14: =Datasets!F129 -> 0.0311 | H14: =Datasets!G129 -> 0.0311 | I14: =Datasets!H129 -> 0.0311 | J14: =Datasets!I129 -> 0.0311 | ... CX14: =Datasets!CW129 -> 0.0309
